{
 "cells": [
  {
   "cell_type": "code",
   "execution_count": 1,
   "id": "a068e35d",
   "metadata": {},
   "outputs": [
    {
     "data": {
      "text/plain": [
       "<queue.Queue at 0x1aaea68d820>"
      ]
     },
     "execution_count": 1,
     "metadata": {},
     "output_type": "execute_result"
    },
    {
     "name": "stderr",
     "output_type": "stream",
     "text": [
      "Error while getting Updates: Conflict: terminated by other getUpdates request; make sure that only one bot instance is running\n",
      "No error handlers are registered, logging exception.\n",
      "Traceback (most recent call last):\n",
      "  File \"C:\\Users\\shahk\\anaconda3\\lib\\site-packages\\telegram\\ext\\updater.py\", line 646, in _network_loop_retry\n",
      "    if not action_cb():\n",
      "  File \"C:\\Users\\shahk\\anaconda3\\lib\\site-packages\\telegram\\ext\\updater.py\", line 597, in polling_action_cb\n",
      "    updates = self.bot.get_updates(\n",
      "  File \"C:\\Users\\shahk\\anaconda3\\lib\\site-packages\\telegram\\ext\\extbot.py\", line 222, in get_updates\n",
      "    updates = super().get_updates(\n",
      "  File \"C:\\Users\\shahk\\anaconda3\\lib\\site-packages\\telegram\\bot.py\", line 130, in decorator\n",
      "    result = func(*args, **kwargs)\n",
      "  File \"C:\\Users\\shahk\\anaconda3\\lib\\site-packages\\telegram\\bot.py\", line 2861, in get_updates\n",
      "    self._post(\n",
      "  File \"C:\\Users\\shahk\\anaconda3\\lib\\site-packages\\telegram\\bot.py\", line 295, in _post\n",
      "    return self.request.post(\n",
      "  File \"C:\\Users\\shahk\\anaconda3\\lib\\site-packages\\telegram\\utils\\request.py\", line 356, in post\n",
      "    result = self._request_wrapper(\n",
      "  File \"C:\\Users\\shahk\\anaconda3\\lib\\site-packages\\telegram\\utils\\request.py\", line 283, in _request_wrapper\n",
      "    raise Conflict(message)\n",
      "telegram.error.Conflict: Conflict: terminated by other getUpdates request; make sure that only one bot instance is running\n",
      "Error while getting Updates: Conflict: terminated by other getUpdates request; make sure that only one bot instance is running\n",
      "No error handlers are registered, logging exception.\n",
      "Traceback (most recent call last):\n",
      "  File \"C:\\Users\\shahk\\anaconda3\\lib\\site-packages\\telegram\\ext\\updater.py\", line 646, in _network_loop_retry\n",
      "    if not action_cb():\n",
      "  File \"C:\\Users\\shahk\\anaconda3\\lib\\site-packages\\telegram\\ext\\updater.py\", line 597, in polling_action_cb\n",
      "    updates = self.bot.get_updates(\n",
      "  File \"C:\\Users\\shahk\\anaconda3\\lib\\site-packages\\telegram\\ext\\extbot.py\", line 222, in get_updates\n",
      "    updates = super().get_updates(\n",
      "  File \"C:\\Users\\shahk\\anaconda3\\lib\\site-packages\\telegram\\bot.py\", line 130, in decorator\n",
      "    result = func(*args, **kwargs)\n",
      "  File \"C:\\Users\\shahk\\anaconda3\\lib\\site-packages\\telegram\\bot.py\", line 2861, in get_updates\n",
      "    self._post(\n",
      "  File \"C:\\Users\\shahk\\anaconda3\\lib\\site-packages\\telegram\\bot.py\", line 295, in _post\n",
      "    return self.request.post(\n",
      "  File \"C:\\Users\\shahk\\anaconda3\\lib\\site-packages\\telegram\\utils\\request.py\", line 356, in post\n",
      "    result = self._request_wrapper(\n",
      "  File \"C:\\Users\\shahk\\anaconda3\\lib\\site-packages\\telegram\\utils\\request.py\", line 283, in _request_wrapper\n",
      "    raise Conflict(message)\n",
      "telegram.error.Conflict: Conflict: terminated by other getUpdates request; make sure that only one bot instance is running\n",
      "Error while getting Updates: Conflict: terminated by other getUpdates request; make sure that only one bot instance is running\n",
      "No error handlers are registered, logging exception.\n",
      "Traceback (most recent call last):\n",
      "  File \"C:\\Users\\shahk\\anaconda3\\lib\\site-packages\\telegram\\ext\\updater.py\", line 646, in _network_loop_retry\n",
      "    if not action_cb():\n",
      "  File \"C:\\Users\\shahk\\anaconda3\\lib\\site-packages\\telegram\\ext\\updater.py\", line 597, in polling_action_cb\n",
      "    updates = self.bot.get_updates(\n",
      "  File \"C:\\Users\\shahk\\anaconda3\\lib\\site-packages\\telegram\\ext\\extbot.py\", line 222, in get_updates\n",
      "    updates = super().get_updates(\n",
      "  File \"C:\\Users\\shahk\\anaconda3\\lib\\site-packages\\telegram\\bot.py\", line 130, in decorator\n",
      "    result = func(*args, **kwargs)\n",
      "  File \"C:\\Users\\shahk\\anaconda3\\lib\\site-packages\\telegram\\bot.py\", line 2861, in get_updates\n",
      "    self._post(\n",
      "  File \"C:\\Users\\shahk\\anaconda3\\lib\\site-packages\\telegram\\bot.py\", line 295, in _post\n",
      "    return self.request.post(\n",
      "  File \"C:\\Users\\shahk\\anaconda3\\lib\\site-packages\\telegram\\utils\\request.py\", line 356, in post\n",
      "    result = self._request_wrapper(\n",
      "  File \"C:\\Users\\shahk\\anaconda3\\lib\\site-packages\\telegram\\utils\\request.py\", line 283, in _request_wrapper\n",
      "    raise Conflict(message)\n",
      "telegram.error.Conflict: Conflict: terminated by other getUpdates request; make sure that only one bot instance is running\n",
      "Error while getting Updates: Conflict: terminated by other getUpdates request; make sure that only one bot instance is running\n",
      "No error handlers are registered, logging exception.\n",
      "Traceback (most recent call last):\n",
      "  File \"C:\\Users\\shahk\\anaconda3\\lib\\site-packages\\telegram\\ext\\updater.py\", line 646, in _network_loop_retry\n",
      "    if not action_cb():\n",
      "  File \"C:\\Users\\shahk\\anaconda3\\lib\\site-packages\\telegram\\ext\\updater.py\", line 597, in polling_action_cb\n",
      "    updates = self.bot.get_updates(\n",
      "  File \"C:\\Users\\shahk\\anaconda3\\lib\\site-packages\\telegram\\ext\\extbot.py\", line 222, in get_updates\n",
      "    updates = super().get_updates(\n",
      "  File \"C:\\Users\\shahk\\anaconda3\\lib\\site-packages\\telegram\\bot.py\", line 130, in decorator\n",
      "    result = func(*args, **kwargs)\n",
      "  File \"C:\\Users\\shahk\\anaconda3\\lib\\site-packages\\telegram\\bot.py\", line 2861, in get_updates\n",
      "    self._post(\n",
      "  File \"C:\\Users\\shahk\\anaconda3\\lib\\site-packages\\telegram\\bot.py\", line 295, in _post\n",
      "    return self.request.post(\n",
      "  File \"C:\\Users\\shahk\\anaconda3\\lib\\site-packages\\telegram\\utils\\request.py\", line 356, in post\n",
      "    result = self._request_wrapper(\n",
      "  File \"C:\\Users\\shahk\\anaconda3\\lib\\site-packages\\telegram\\utils\\request.py\", line 283, in _request_wrapper\n",
      "    raise Conflict(message)\n",
      "telegram.error.Conflict: Conflict: terminated by other getUpdates request; make sure that only one bot instance is running\n",
      "Error while getting Updates: Conflict: terminated by other getUpdates request; make sure that only one bot instance is running\n",
      "No error handlers are registered, logging exception.\n",
      "Traceback (most recent call last):\n",
      "  File \"C:\\Users\\shahk\\anaconda3\\lib\\site-packages\\telegram\\ext\\updater.py\", line 646, in _network_loop_retry\n",
      "    if not action_cb():\n",
      "  File \"C:\\Users\\shahk\\anaconda3\\lib\\site-packages\\telegram\\ext\\updater.py\", line 597, in polling_action_cb\n",
      "    updates = self.bot.get_updates(\n",
      "  File \"C:\\Users\\shahk\\anaconda3\\lib\\site-packages\\telegram\\ext\\extbot.py\", line 222, in get_updates\n",
      "    updates = super().get_updates(\n",
      "  File \"C:\\Users\\shahk\\anaconda3\\lib\\site-packages\\telegram\\bot.py\", line 130, in decorator\n",
      "    result = func(*args, **kwargs)\n",
      "  File \"C:\\Users\\shahk\\anaconda3\\lib\\site-packages\\telegram\\bot.py\", line 2861, in get_updates\n",
      "    self._post(\n",
      "  File \"C:\\Users\\shahk\\anaconda3\\lib\\site-packages\\telegram\\bot.py\", line 295, in _post\n",
      "    return self.request.post(\n",
      "  File \"C:\\Users\\shahk\\anaconda3\\lib\\site-packages\\telegram\\utils\\request.py\", line 356, in post\n",
      "    result = self._request_wrapper(\n",
      "  File \"C:\\Users\\shahk\\anaconda3\\lib\\site-packages\\telegram\\utils\\request.py\", line 283, in _request_wrapper\n",
      "    raise Conflict(message)\n",
      "telegram.error.Conflict: Conflict: terminated by other getUpdates request; make sure that only one bot instance is running\n",
      "Error while getting Updates: Conflict: terminated by other getUpdates request; make sure that only one bot instance is running\n",
      "No error handlers are registered, logging exception.\n",
      "Traceback (most recent call last):\n",
      "  File \"C:\\Users\\shahk\\anaconda3\\lib\\site-packages\\telegram\\ext\\updater.py\", line 646, in _network_loop_retry\n",
      "    if not action_cb():\n",
      "  File \"C:\\Users\\shahk\\anaconda3\\lib\\site-packages\\telegram\\ext\\updater.py\", line 597, in polling_action_cb\n",
      "    updates = self.bot.get_updates(\n",
      "  File \"C:\\Users\\shahk\\anaconda3\\lib\\site-packages\\telegram\\ext\\extbot.py\", line 222, in get_updates\n",
      "    updates = super().get_updates(\n",
      "  File \"C:\\Users\\shahk\\anaconda3\\lib\\site-packages\\telegram\\bot.py\", line 130, in decorator\n",
      "    result = func(*args, **kwargs)\n",
      "  File \"C:\\Users\\shahk\\anaconda3\\lib\\site-packages\\telegram\\bot.py\", line 2861, in get_updates\n",
      "    self._post(\n",
      "  File \"C:\\Users\\shahk\\anaconda3\\lib\\site-packages\\telegram\\bot.py\", line 295, in _post\n",
      "    return self.request.post(\n",
      "  File \"C:\\Users\\shahk\\anaconda3\\lib\\site-packages\\telegram\\utils\\request.py\", line 356, in post\n",
      "    result = self._request_wrapper(\n",
      "  File \"C:\\Users\\shahk\\anaconda3\\lib\\site-packages\\telegram\\utils\\request.py\", line 283, in _request_wrapper\n",
      "    raise Conflict(message)\n",
      "telegram.error.Conflict: Conflict: terminated by other getUpdates request; make sure that only one bot instance is running\n",
      "Error while getting Updates: Conflict: terminated by other getUpdates request; make sure that only one bot instance is running\n",
      "No error handlers are registered, logging exception.\n",
      "Traceback (most recent call last):\n",
      "  File \"C:\\Users\\shahk\\anaconda3\\lib\\site-packages\\telegram\\ext\\updater.py\", line 646, in _network_loop_retry\n",
      "    if not action_cb():\n",
      "  File \"C:\\Users\\shahk\\anaconda3\\lib\\site-packages\\telegram\\ext\\updater.py\", line 597, in polling_action_cb\n",
      "    updates = self.bot.get_updates(\n",
      "  File \"C:\\Users\\shahk\\anaconda3\\lib\\site-packages\\telegram\\ext\\extbot.py\", line 222, in get_updates\n",
      "    updates = super().get_updates(\n",
      "  File \"C:\\Users\\shahk\\anaconda3\\lib\\site-packages\\telegram\\bot.py\", line 130, in decorator\n",
      "    result = func(*args, **kwargs)\n",
      "  File \"C:\\Users\\shahk\\anaconda3\\lib\\site-packages\\telegram\\bot.py\", line 2861, in get_updates\n",
      "    self._post(\n",
      "  File \"C:\\Users\\shahk\\anaconda3\\lib\\site-packages\\telegram\\bot.py\", line 295, in _post\n",
      "    return self.request.post(\n",
      "  File \"C:\\Users\\shahk\\anaconda3\\lib\\site-packages\\telegram\\utils\\request.py\", line 356, in post\n",
      "    result = self._request_wrapper(\n",
      "  File \"C:\\Users\\shahk\\anaconda3\\lib\\site-packages\\telegram\\utils\\request.py\", line 283, in _request_wrapper\n",
      "    raise Conflict(message)\n",
      "telegram.error.Conflict: Conflict: terminated by other getUpdates request; make sure that only one bot instance is running\n",
      "Error while getting Updates: Conflict: terminated by other getUpdates request; make sure that only one bot instance is running\n",
      "No error handlers are registered, logging exception.\n",
      "Traceback (most recent call last):\n",
      "  File \"C:\\Users\\shahk\\anaconda3\\lib\\site-packages\\telegram\\ext\\updater.py\", line 646, in _network_loop_retry\n",
      "    if not action_cb():\n",
      "  File \"C:\\Users\\shahk\\anaconda3\\lib\\site-packages\\telegram\\ext\\updater.py\", line 597, in polling_action_cb\n",
      "    updates = self.bot.get_updates(\n",
      "  File \"C:\\Users\\shahk\\anaconda3\\lib\\site-packages\\telegram\\ext\\extbot.py\", line 222, in get_updates\n",
      "    updates = super().get_updates(\n",
      "  File \"C:\\Users\\shahk\\anaconda3\\lib\\site-packages\\telegram\\bot.py\", line 130, in decorator\n",
      "    result = func(*args, **kwargs)\n",
      "  File \"C:\\Users\\shahk\\anaconda3\\lib\\site-packages\\telegram\\bot.py\", line 2861, in get_updates\n",
      "    self._post(\n",
      "  File \"C:\\Users\\shahk\\anaconda3\\lib\\site-packages\\telegram\\bot.py\", line 295, in _post\n",
      "    return self.request.post(\n",
      "  File \"C:\\Users\\shahk\\anaconda3\\lib\\site-packages\\telegram\\utils\\request.py\", line 356, in post\n",
      "    result = self._request_wrapper(\n",
      "  File \"C:\\Users\\shahk\\anaconda3\\lib\\site-packages\\telegram\\utils\\request.py\", line 283, in _request_wrapper\n",
      "    raise Conflict(message)\n",
      "telegram.error.Conflict: Conflict: terminated by other getUpdates request; make sure that only one bot instance is running\n",
      "Error while getting Updates: Conflict: terminated by other getUpdates request; make sure that only one bot instance is running\n",
      "No error handlers are registered, logging exception.\n",
      "Traceback (most recent call last):\n",
      "  File \"C:\\Users\\shahk\\anaconda3\\lib\\site-packages\\telegram\\ext\\updater.py\", line 646, in _network_loop_retry\n",
      "    if not action_cb():\n",
      "  File \"C:\\Users\\shahk\\anaconda3\\lib\\site-packages\\telegram\\ext\\updater.py\", line 597, in polling_action_cb\n",
      "    updates = self.bot.get_updates(\n",
      "  File \"C:\\Users\\shahk\\anaconda3\\lib\\site-packages\\telegram\\ext\\extbot.py\", line 222, in get_updates\n",
      "    updates = super().get_updates(\n",
      "  File \"C:\\Users\\shahk\\anaconda3\\lib\\site-packages\\telegram\\bot.py\", line 130, in decorator\n",
      "    result = func(*args, **kwargs)\n",
      "  File \"C:\\Users\\shahk\\anaconda3\\lib\\site-packages\\telegram\\bot.py\", line 2861, in get_updates\n",
      "    self._post(\n",
      "  File \"C:\\Users\\shahk\\anaconda3\\lib\\site-packages\\telegram\\bot.py\", line 295, in _post\n",
      "    return self.request.post(\n",
      "  File \"C:\\Users\\shahk\\anaconda3\\lib\\site-packages\\telegram\\utils\\request.py\", line 356, in post\n",
      "    result = self._request_wrapper(\n",
      "  File \"C:\\Users\\shahk\\anaconda3\\lib\\site-packages\\telegram\\utils\\request.py\", line 283, in _request_wrapper\n",
      "    raise Conflict(message)\n",
      "telegram.error.Conflict: Conflict: terminated by other getUpdates request; make sure that only one bot instance is running\n",
      "Error while getting Updates: Conflict: terminated by other getUpdates request; make sure that only one bot instance is running\n",
      "No error handlers are registered, logging exception.\n",
      "Traceback (most recent call last):\n",
      "  File \"C:\\Users\\shahk\\anaconda3\\lib\\site-packages\\telegram\\ext\\updater.py\", line 646, in _network_loop_retry\n",
      "    if not action_cb():\n",
      "  File \"C:\\Users\\shahk\\anaconda3\\lib\\site-packages\\telegram\\ext\\updater.py\", line 597, in polling_action_cb\n",
      "    updates = self.bot.get_updates(\n",
      "  File \"C:\\Users\\shahk\\anaconda3\\lib\\site-packages\\telegram\\ext\\extbot.py\", line 222, in get_updates\n",
      "    updates = super().get_updates(\n",
      "  File \"C:\\Users\\shahk\\anaconda3\\lib\\site-packages\\telegram\\bot.py\", line 130, in decorator\n",
      "    result = func(*args, **kwargs)\n",
      "  File \"C:\\Users\\shahk\\anaconda3\\lib\\site-packages\\telegram\\bot.py\", line 2861, in get_updates\n",
      "    self._post(\n",
      "  File \"C:\\Users\\shahk\\anaconda3\\lib\\site-packages\\telegram\\bot.py\", line 295, in _post\n",
      "    return self.request.post(\n",
      "  File \"C:\\Users\\shahk\\anaconda3\\lib\\site-packages\\telegram\\utils\\request.py\", line 356, in post\n",
      "    result = self._request_wrapper(\n",
      "  File \"C:\\Users\\shahk\\anaconda3\\lib\\site-packages\\telegram\\utils\\request.py\", line 283, in _request_wrapper\n",
      "    raise Conflict(message)\n",
      "telegram.error.Conflict: Conflict: terminated by other getUpdates request; make sure that only one bot instance is running\n",
      "Error while getting Updates: Conflict: terminated by other getUpdates request; make sure that only one bot instance is running\n",
      "No error handlers are registered, logging exception.\n",
      "Traceback (most recent call last):\n",
      "  File \"C:\\Users\\shahk\\anaconda3\\lib\\site-packages\\telegram\\ext\\updater.py\", line 646, in _network_loop_retry\n",
      "    if not action_cb():\n",
      "  File \"C:\\Users\\shahk\\anaconda3\\lib\\site-packages\\telegram\\ext\\updater.py\", line 597, in polling_action_cb\n",
      "    updates = self.bot.get_updates(\n",
      "  File \"C:\\Users\\shahk\\anaconda3\\lib\\site-packages\\telegram\\ext\\extbot.py\", line 222, in get_updates\n",
      "    updates = super().get_updates(\n",
      "  File \"C:\\Users\\shahk\\anaconda3\\lib\\site-packages\\telegram\\bot.py\", line 130, in decorator\n",
      "    result = func(*args, **kwargs)\n",
      "  File \"C:\\Users\\shahk\\anaconda3\\lib\\site-packages\\telegram\\bot.py\", line 2861, in get_updates\n",
      "    self._post(\n",
      "  File \"C:\\Users\\shahk\\anaconda3\\lib\\site-packages\\telegram\\bot.py\", line 295, in _post\n",
      "    return self.request.post(\n",
      "  File \"C:\\Users\\shahk\\anaconda3\\lib\\site-packages\\telegram\\utils\\request.py\", line 356, in post\n",
      "    result = self._request_wrapper(\n",
      "  File \"C:\\Users\\shahk\\anaconda3\\lib\\site-packages\\telegram\\utils\\request.py\", line 283, in _request_wrapper\n",
      "    raise Conflict(message)\n",
      "telegram.error.Conflict: Conflict: terminated by other getUpdates request; make sure that only one bot instance is running\n"
     ]
    }
   ],
   "source": [
    "from telegram.ext.updater import Updater\n",
    "from telegram.update import Update\n",
    "from telegram.ext.callbackcontext import CallbackContext\n",
    "from telegram.ext.commandhandler import CommandHandler\n",
    "from telegram.ext.messagehandler import MessageHandler\n",
    "from telegram.ext.filters import Filters\n",
    "\n",
    "updater = Updater(\"2051768905:AAGL22V50C3dL8QNIgbMrqhOcmMCjeMg1LA\",use_context=True)\n",
    "\n",
    "\n",
    "def start(update: Update, context: CallbackContext):\n",
    "\tupdate.message.reply_text(\"Hello, my name is Kintur. Welcome to my bot.Please write /help to see commands available.\")\n",
    "        \n",
    "def help(update: Update, context: CallbackContext):\n",
    "\tupdate.message.reply_text(\"\"\"Available Commands :-\n",
    "\t/youtube - To get the youtube URL\n",
    "\t/linkedin - To get the LinkedIn profile URL\n",
    "\t/gmail - To get gmail URL\n",
    "\t/geeks - To get the GeeksforGeeks URL\"\"\")\n",
    "\n",
    "\n",
    "def gmail_url(update: Update, context: CallbackContext):\n",
    "\tupdate.message.reply_text(\"htps://mail.google.com/mail/u/0/#inbox\")\n",
    "\n",
    "\n",
    "def youtube_url(update: Update, context: CallbackContext):\n",
    "\tupdate.message.reply_text(\"https://www.youtube.com/\")\n",
    "\n",
    "\n",
    "def linkedIn_url(update: Update, context: CallbackContext):\n",
    "\tupdate.message.reply_text(\"https://www.linkedin.com/in/kintur-shah-a81134210/\")\n",
    "\n",
    "\n",
    "def geeks_url(update: Update, context: CallbackContext):\n",
    "\tupdate.message.reply_text(\"https://www.geeksforgeeks.org/\")\n",
    "\n",
    "\n",
    "def unknown(update: Update, context: CallbackContext):\n",
    "\tupdate.message.reply_text(\"Sorry '%s' is not a valid command\" % update.message.text)\n",
    "\n",
    "\n",
    "def unknown_text(update: Update, context: CallbackContext):\n",
    "\tupdate.message.reply_text(\"Sorry I can't recognize you , you said '%s'\" % update.message.text)\n",
    "\n",
    "        \n",
    "updater.dispatcher.add_handler(CommandHandler('start', start))\n",
    "updater.dispatcher.add_handler(CommandHandler('youtube', youtube_url))\n",
    "updater.dispatcher.add_handler(CommandHandler('help', help))\n",
    "updater.dispatcher.add_handler(CommandHandler('linkedin', linkedIn_url))\n",
    "updater.dispatcher.add_handler(CommandHandler('gmail', gmail_url))\n",
    "updater.dispatcher.add_handler(CommandHandler('geeks', geeks_url))\n",
    "updater.dispatcher.add_handler(MessageHandler(Filters.text, unknown))\n",
    "updater.dispatcher.add_handler(MessageHandler(\n",
    "\tFilters.command, unknown)) # Filters out unknown commands\n",
    "\n",
    "# Filters out unknown messages.\n",
    "updater.dispatcher.add_handler(MessageHandler(Filters.text, unknown_text))\n",
    "\n",
    "updater.start_polling()"
   ]
  },
  {
   "cell_type": "code",
   "execution_count": null,
   "id": "8e117517",
   "metadata": {},
   "outputs": [],
   "source": []
  }
 ],
 "metadata": {
  "kernelspec": {
   "display_name": "Python 3",
   "language": "python",
   "name": "python3"
  },
  "language_info": {
   "codemirror_mode": {
    "name": "ipython",
    "version": 3
   },
   "file_extension": ".py",
   "mimetype": "text/x-python",
   "name": "python",
   "nbconvert_exporter": "python",
   "pygments_lexer": "ipython3",
   "version": "3.8.8"
  }
 },
 "nbformat": 4,
 "nbformat_minor": 5
}
